[ERROR] [2016-10-02 22:25:40] [base] [3272] [5948] [Internal Server Error: /admin/storage/product/1594/change/]
Traceback (most recent call last):
  File "C:\Python34\lib\site-packages\django\core\handlers\base.py", line 149, in get_response
    response = self.process_exception_by_middleware(e, request)
  File "C:\Python34\lib\site-packages\django\core\handlers\base.py", line 147, in get_response
    response = wrapped_callback(request, *callback_args, **callback_kwargs)
  File "C:\Python34\lib\site-packages\django\views\generic\base.py", line 68, in view
    return self.dispatch(request, *args, **kwargs)
  File "C:\Python34\lib\site-packages\django\utils\decorators.py", line 67, in _wrapper
    return bound_func(*args, **kwargs)
  File "C:\Python34\lib\site-packages\django\contrib\auth\decorators.py", line 23, in _wrapped_view
    return view_func(request, *args, **kwargs)
  File "C:\Python34\lib\site-packages\django\utils\decorators.py", line 63, in bound_func
    return func.__get__(self, type(self))(*args2, **kwargs2)
  File "C:/Users/nemodeveloper/PycharmProjects/hookah_crm\src\apps\csa\csa_base.py", line 22, in dispatch
    return super(AdminInMixin, self).dispatch(*args, **kwargs)
  File "C:\Python34\lib\site-packages\django\utils\decorators.py", line 67, in _wrapper
    return bound_func(*args, **kwargs)
  File "C:\Python34\lib\site-packages\django\contrib\auth\decorators.py", line 23, in _wrapped_view
    return view_func(request, *args, **kwargs)
  File "C:\Python34\lib\site-packages\django\utils\decorators.py", line 63, in bound_func
    return func.__get__(self, type(self))(*args2, **kwargs2)
  File "C:/Users/nemodeveloper/PycharmProjects/hookah_crm\src\apps\csa\csa_base.py", line 14, in dispatch
    return super(LoggedInMixin, self).dispatch(*args, **kwargs)
  File "C:\Python34\lib\site-packages\django\views\generic\base.py", line 88, in dispatch
    return handler(request, *args, **kwargs)
  File "C:\Python34\lib\site-packages\django\views\generic\edit.py", line 275, in get
    return super(BaseUpdateView, self).get(request, *args, **kwargs)
  File "C:\Python34\lib\site-packages\django\views\generic\edit.py", line 213, in get
    return self.render_to_response(self.get_context_data())
  File "C:/Users/nemodeveloper/PycharmProjects/hookah_crm\src\apps\storage\views.py", line 60, in get_context_data
    raise Exception('test for log exception!')
Exception: test for log exception!
